Workbook

Sheet Resumen
A1: TransportesNova — Análisis Comparativo de Costos por Metodología
A2: Basado en el backlog real de Jira · 92 Historias de Usuario · 623 Story Points
A4: Métrica | B4: SCRUM | C4: KANBAN | D4: SCRUMBAN | E4: XP | F4: WSF
A5: Duración del Proyecto | B5: =SCRUM!B19&" meses" -> 10,5511932255581 meses | C5: =KANBAN!B20&" meses" -> 20 meses | D5: =SCRUMBAN!B22/2&" meses build" -> 12,5 meses build | E5: =XP!B19&" meses" -> 11 meses | F5: =('Water Scrum Fall'!B14+'Water Scrum Fall'!B25+'Water Scrum Fall'!B40)&" meses" -> 14,0511932255581 meses
A6: Total Story Points / Historias | B6: =SCRUM!B14&" SP" -> 623 SP | C6: =74&" tareas" -> 74 tareas | D6: =SCRUMBAN!B20&" SP" -> 623 SP | E6: =XP!B10&" SP" -> 623 SP | F6: ="623 SP + Docs" -> 623 SP + Docs
A7: Costo Total del Proyecto (Interno) | B7: =SCRUM!B24 -> 514250 | C7: =KANBAN!B25 -> 935000 | D7: =SCRUMBAN!B40 -> 423087.5 | E7: =XP!B32 -> 514250 | F7: ='Water Scrum Fall'!B64 -> 819168.28
A8: Ingreso Total del Proyecto (Venta) | B8: =SCRUM!B25 -> 1067925.8 | C8: =KANBAN!B24 -> 2400000 | D8: =SCRUMBAN!B39 -> 1057718.8 | E8: =XP!B27*XP!B19 -> 1320000 | F8: ='Water Scrum Fall'!B69 -> 1489396.9
A9: Margen Bruto | B9: =SCRUM!B26 -> 553675.83 | C9: =KANBAN!B26 -> 1465000 | D9: =SCRUMBAN!B43 -> 634631.25 | E9: =E8-E7 -> 805750 | F9: ='Water Scrum Fall'!B71 -> 670228.6
A10: Margen Bruto % (sobre venta) | B10: =SCRUM!B26/SCRUM!B25 -> 0.51845907 | C10: =KANBAN!B26/KANBAN!B24 -> 0.61041667 | D10: =SCRUMBAN!B43/SCRUMBAN!B39 -> 0.6 | E10: =E9/E8 -> 0.61041667 | F10: =F9/F8 -> 0.45
A11: Costo por Unidad de Trabajo | B11: =SCRUM!B24/SCRUM!B14&" Q/SP" -> 825,441412520064 Q/SP | C11: =KANBAN!B25/KANBAN!B15&" Q/hist" -> 7923,72881355932 Q/hist | D11: Ver hoja SCRUMBAN | E11: =XP!B32/XP!B10&" Q/SP" -> 825,441412520064 Q/SP | F11: ="Precio fijo cerrado" -> Precio fijo cerrado
A12: Equipo Mensual (costo interno) | B12: =Equipo!E13 -> 46750 | C12: =Equipo!E13 -> 46750 | D12: =Equipo!E13 -> 46750 | E12: =Equipo!E13 -> 46750 | F12: =Equipo!E13 -> 46750
A14: NOTAS METODOLÓGICAS
A15: SCRUM: | B15: Iteraciones fijas (sprints). Mejor para proyectos con alcance definido y necesidad de entregas periódicas predecibles.
A16: KANBAN: | B16: Flujo continuo sin sprints. Mejor para proyectos con requerimientos cambiantes; duración mayor pero más flexible.
A17: SCRUMBAN: | B17: Híbrido: Build con disciplina de sprints + Run con flujo Kanban continuo. Ideal para equipos que entregan Y mantienen.
A18: XP: | B18: Enfoque en calidad: pair programming, TDD, integración continua. Mejor para proyectos donde la calidad del código es crítica.
A19: WATER-SCRUM-FALL: | B19: Híbrido tradicional+ágil: planificación cascada inicial + desarrollo Scrum + despliegue cascada final. Precio fijo cerrado. Ideal para empresas con procesos formales y gobierno corporativo.

Sheet SCRUM
A1: SCRUM — Estimación de Costos del Proyecto
A3: SUPUESTOS DE EQUIPO
A4: Costo Total del Equipo / Mes | B4: =Equipo!E12 -> 93500 | C4: Q/mes | D4: Vinculado desde hoja Equipo
A5: Costo Interno (50% FTE) / Mes | B5: =Equipo!E13 -> 46750 | C5: Q/mes | D5: Vinculado desde hoja Equipo
A7: SUPUESTOS DE METODOLOGÍA SCRUM
A8: Velocidad del Equipo | B8: 30 | C8: SP / sprint | D8: Story Points por sprint de 2 semanas
A9: Duración del Sprint | B9: 2 | C9: semanas
A10: Factor de Holgura (buffer) | B10: 1.1 | D10: 10% de margen sobre estimación base
A11: Precio de Venta por Sprint | B11: =B4/B9 -> 46750 | C11: Q / sprint | D11: Tarifa comercial acordada con cliente
A13: BACKLOG — STORY POINTS TOTALES
A14: TOTAL STORY POINTS DEL PROYECTO | B14: =Backlog!F150 -> 623 | C14: SP totales
A16: CÁLCULOS DEL PROYECTO
A17: Total Sprints (sin holgura) | B17: =B14/B8 -> 20.766667 | C17: sprints | D17: SP totales ÷ velocidad
A18: Total Sprints (con holgura) | B18: =B17*B10 -> 22.843333 | C18: sprints | D18: × factor 10 de holgura
A19: Duración Total del Proyecto | B19: =B18*B9/4.33 -> 10.551193 | C19: meses | D19: Semanas totales ÷ 4.33 semanas/mes
A20: Meses | B20: 11 | C20: Meses
A21: Costo Interno por Sprint | B21: =B5/(4.33/B9) -> 21593.533 | C21: Q/sprint | D21: Costo mensual interno ÷ sprints por mes
A22: mesis
A23: RESUMEN FINANCIERO
A24: Costo Total del Proyecto (Interno) | B24: =B20*B11 -> 514250 | C24: Q
A25: Ingreso Total del Proyecto (Venta) | B25: =B18*B11 -> 1067925.8 | C25: Q
A26: Margen Bruto | B26: =B25-B24 -> 553675.83 | C26: Q
A27: Margen Bruto % (sobre venta) | B27: =B26/B25 -> 0.51845907 | C27: % | D27: Ingreso menos Costo, dividido Ingreso
A28: Markup % (margen sobre costo) | B28: =B26/B24 -> 1.0766667 | C28: % | D28: Ingreso menos Costo, dividido Costo
A29: Costo por Story Point | B29: =B24/B14 -> 825.44141 | C29: Q/SP | D29: Costo total ÷ SP totales
A31: Leyenda: Amarillo = input/supuesto editable Azul = fórmula calculada Verde = vinculado desde otra hoja
A33: VELOCIDAD DEL EQUIPO DE TRABAJO
A34: Senior 1: | B34: 18–20 | C34: SP
A35: Senior 2: | B35: 18–20 | C35: SP
A36: Junior 1: | B36: 10–12 | C36: SP
A37: Junior 2: | B37: 10–12 | C37: SP

Sheet SCRUMBAN
A1: SCRUMBAN — Estimación de Costos del Proyecto
A3: SUPUESTOS DE EQUIPO
A4: Costo Total del Equipo / Mes | B4: =Equipo!E13 -> 46750 | C4: Q/mes | D4: Vinculado desde hoja Equipo
A5: Costo Interno (50% FTE) / Mes | B5: =Equipo!E13 -> 46750 | C5: Q/mes | D5: Costo asignado al proyecto (base para márgenes)
A7: SUPUESTOS SCRUMBAN — FASE BUILD (Sprints Scrum)
A8: Velocidad del Equipo | B8: 30 | C8: SP/sprint | D8: Story Points por sprint de 2 semanas
A9: Duración del Sprint | B9: 2 | C9: semanas
A10: Factor Holgura Build | B10: 1.2 | D10: 20% buffer para fase de desarrollo
A11: Capacidad BUILD (desarrollo activo) | B11: 0.7 | C11: =B11 -> 0.7 | D11: 70% del equipo en features nuevas
A12: Capacidad RUN (operación/mantenimiento) | B12: 0.3 | C12: =B12 -> 0.3 | D12: 30% del equipo en soporte continuo
A14: SUPUESTOS SCRUMBAN — FASE RUN (Kanban continuo)
A15: Lead Time promedio (fase Run) | B15: 10 | C15: días | D15: Días por historia en modo operativo
A16: WIP Limit (fase Run) | B16: 3 | C16: tareas
A17: Días laborales por mes | B17: 20 | C17: días/mes
A19: BACKLOG
A20: Total Story Points | B20: =Backlog!F150 -> 623 | C20: SP
A21: Sprints | B21: =B20/B8 -> 20.766667 | C21: sprints
A22: Sprints con holgura | B22: =ROUND(B21*B10,0) -> 25
A23: COSTOS BUILD Y COSTOS RUN
A24: Costo Build | B24: =B4*B11 -> 32725
A25: Costo Run | B25: =B4*B12 -> 14025
B26: =SUM(B24:B25) -> 46750
A27: MARGEN OBJETIVO
A28: Margen objetivo | B28: 0.6
A31: PRECIOS
A32: Precio Build | B32: =B24/(1-B28) -> 81812.5
A33: Precio Run | B33: =B25/(1-B28) -> 35062.5
A35: Precio Build por sprint | B35: =B32/B9 -> 40906.25
A38: INGRESOS Y COSTOS
A39: Ingreso Total | B39: =B33+(B22*B35) -> 1057718.8
A40: Costo Total | B40: =((B24)*(B22/B9))+(B25) -> 423087.5
A42: MARGEN BRUTO Y PORCENTAJE DE MARGEN
A43: Margen bruto | B43: =B39-B40 -> 634631.25
A44: Margen % | B44: =B43/B39 -> 0.6

Sheet KANBAN
A1: KANBAN — Estimación de Costos del Proyecto
A3: SUPUESTOS DE EQUIPO
A4: Costo Total del Equipo / Mes | B4: =Equipo!E12 -> 93500 | C4: Q/mes | D4: Vinculado desde hoja Equipo
A5: Costo Interno (50% FTE) / Mes | B5: =Equipo!E13 -> 46750 | C5: Q/mes | D5: Vinculado desde hoja Equipo
A7: SUPUESTOS DE METODOLOGÍA KANBAN
A8: Cycle Time promedio | B8: 7 | C8: días | D8: Días efectivos de trabajo por historia
A9: Lead Time promedio | B9: 10 | C9: días | D9: Días totales incluyendo cola/espera
A10: WIP Limit (tareas en paralelo) | B10: 3 | C10: tareas | D10: Límite de trabajo en progreso simultáneo
A11: Días laborales por mes | B11: 20 | C11: días/mes | D11: Días hábiles de trabajo mensual
A12: Precio de Venta / Mes | B12: 120000 | C12: Q/mes | D12: Tarifa mensual comercial cobrada al cliente
A14: VOLUMEN DE TRABAJO — BACKLOG
A15: Total Historias de Usuario (Backlog) | B15: =Backlog!A151 -> 118 | C15: historias | D15: Historias activas del backlog en Jira (10 épicas)
A17: CÁLCULOS DE FLUJO
A18: Total Días de Trabajo | B18: =B15*B9 -> 1180 | C18: días | D18: Historias × Lead Time
A19: Días Ajustados por WIP | B19: =B18/B10 -> 393.33333 | C19: días | D19: Lead Time total ÷ WIP Limit (paralelismo)
A20: Duración Total del Proyecto | B20: =CEILING(B19/B11,1) -> 20 | C20: meses | D20: Días ajustados ÷ días laborales/mes (redondeado arriba)
A21: Throughput (historias / mes) | B21: =B10*B11/B9 -> 6 | C21: hist/mes | D21: WIP × días/mes ÷ Lead Time
A23: RESUMEN FINANCIERO
A24: Ingreso Total del Proyecto (Venta) | B24: =B20*B12 -> 2400000 | C24: Q
A25: Costo Total del Proyecto (Interno) | B25: =B20*B5 -> 935000 | C25: Q
A26: Margen Bruto | B26: =B24-B25 -> 1465000 | C26: Q
A27: Margen Bruto % (sobre venta) | B27: =B26/B24 -> 0.61041667 | C27: %
A28: Markup % (margen sobre costo) | B28: =B26/B25 -> 1.5668449 | C28: %
A29: Costo por Historia de Usuario | B29: =B25/B15 -> 7923.7288 | C29: Q/hist

Sheet XP
A1: EXTREME PROGRAMMING (XP) — Estimación de Costos del Proyecto
A2: TransportesNova — Basado en metodología XP: enfoque en calidad del código, pair programming, pruebas continuas
A4: 1. BURN RATE — Costo Real Mensual del Equipo
A5: Fórmula: Costo real mensual = Σ (Costo persona × FTE)
A7: BURN RATE (Costo real mensual) | D7: =Equipo!E13 -> 46750
A9: 2. PARÁMETROS DEL PROYECTO
A10: Total Story Points del Proyecto | B10: =Backlog!F150 -> 623 | C10: SP | D10: Backlog real con 92 historias en 10 épicas
A11: Velocidad del Equipo | B11: 30 | C11: SP/sprint | D11: Story Points completados por sprint
A12: Duración del Sprint | B12: 2 | C12: semanas | D12: Iteración corta estilo XP
A13: Factor de Holgura (buffer) | B13: 46296 | D13: 10% de margen sobre estimación base
A15: 3. CÁLCULOS DEL PROYECTO
A16: Total Sprints (sin holgura) | B16: =B10/B11 -> 20.766667 | C16: sprints | D16: SP totales ÷ velocidad
A17: Total Sprints (con holgura) | B17: =B16+B16*0.1 -> 22.843333 | C17: sprints | D17: × factor de holgura, redondeado
A18: Duración Total del Proyecto | B18: =(B17*2)/4.33 -> 10.551193 | C18: meses | D18: Semanas totales ÷ 4.33 semanas/mes
B19: 11 | C19: Meses
A20: 4. PRECIO AL CLIENTE (Markup Libre — estilo PDF profesor)
A21: Considera: costo real del equipo + riesgo del proyecto + gastos administrativos
A22: Margen objetivo (%) | B22: 0.6 | C22: % | D22: Margen sobre venta (PDF: ~24%)
A23: Precio al cliente mensual | B23: =D7/(1-B22) -> 116875 | C23: Q/mes | D23: Costo real mensual / (1 - margen)
A25: 5. RESUMEN FINANCIERO MENSUAL (estilo PDF profesor)
A26: Costo real mensual (Burn Rate) | B26: =D7 -> 46750 | D26: Σ (Costo persona × FTE)
A27: Precio al cliente mensual | B27: 120000 | D27: Precio acordado con cliente
A28: Margen Bruto mensual | B28: =B27-B26 -> 73250 | D28: Margen Bruto = Precio − Costo Real
A29: Margen % mensual | B29: =(B28/B27)*100 -> 61.041667 | D29: Margen % = (Margen Bruto ÷ Precio) × 100
A31: 6. RESUMEN FINANCIERO — TOTAL DEL PROYECTO
A32: Costo Total del Proyecto | B32: =B26*B19 -> 514250 | D32: Burn Rate × Duración en meses
A33: Venta Proyecto | B33: =B27*B19 -> 1320000
A34: Ganancia Total | B34: =B33-B32 -> 805750

Sheet Water Scrum Fall
A1: WATER-SCRUM-FALL — Estimación de Costos del Proyecto
A2: Metodología híbrida: Water (cascada inicial) → Scrum (desarrollo ágil) → Fall (despliegue cascada). Contrato de precio fijo.
A4: FASE 1 — WATER (Planificación inicial - Cascada)
A5: Lógica de costo: Costo Mensual del Equipo Water × Duración en meses. Solo participan PO, Seniors y SM. Devs aún no están activos.
A7: Rol | B7: Salario (Q) | C7: FTE | D7: Costo Asignado (Q) | G7: Función en Water
A8: Product Owner | B8: 22000 | C8: 1 | D8: =B8*C8 -> 22000 | G8: Definir backlog detallado y validar requerimientos
A9: Senior - Cloud Engineer | B9: 15500 | C9: 1 | D9: =B9*C9 -> 15500 | G9: Diseño arquitectónico técnico del sistema
A10: Senior - DevOps | B10: 14000 | C10: 0.5 | D10: =B10*C10 -> 7000 | G10: Planificación de infraestructura y CI/CD
A11: SM/Facilitador | B11: 16500 | C11: 0.5 | D11: =B11*C11 -> 8250 | G11: Coordinación, contratos, plan de gestión
A12: COSTO MENSUAL EQUIPO WATER | D12: =SUM(D8:D11) -> 52750 | G12: Σ Salario × FTE de roles activos
A14: Duración fase Water | B14: 2 | C14: meses | G14: Análisis, diseño arquitectónico, contratos
A15: COSTO TOTAL FASE WATER | B15: =D12*B14 -> 105500 | G15: Fórmula: costo mensual × Duración
A18: FASE 2 — SCRUM (Desarrollo iterativo - Ágil)
A19: Lógica de costo: Reutilizamos cálculos de la hoja SCRUM. Equipo completo activo durante sprints.
A21: Costo Interno Mensual (Equipo completo) | B21: =SCRUM!B5 -> 46750 | C21: Q/mes | G21: Vinculado de hoja SCRUM (50% FTE)
A22: Story Points Totales | B22: =SCRUM!B14 -> 623 | C22: SP | G22: Vinculado de hoja SCRUM
A23: Velocidad del Equipo | B23: =SCRUM!B8 -> 30 | C23: SP/sprint | G23: Vinculado de hoja SCRUM
A24: Total Sprints (con holgura) | B24: =SCRUM!B18 -> 22.843333 | C24: sprints | G24: Vinculado de hoja SCRUM
A25: Duración fase Scrum | B25: =SCRUM!B19 -> 10.551193 | C25: meses | G25: Vinculado de hoja SCRUM
A27: COSTO TOTAL FASE SCRUM | B27: =B21*B25 -> 493268.28 | G27: Vinculado: Costo total del proyecto Scrum
A30: FASE 3 — FALL (Despliegue y cierre - Cascada)
A31: Lógica de costo: Costo mensual × duración. Equipo reducido: QA, Seniors, PO parcial. Devs salen del proyecto.
A33: Rol | B33: Salario (Q) | C33: FTE | D33: Costo Asignado (Q) | G33: Función en Fall
A34: QA Engineer | B34: 7500 | C34: 1 | D34: =B34*C34 -> 7500 | G34: Pruebas finales intensivas, UAT
A35: Senior - DevOps | B35: 14000 | C35: 1 | D35: =B35*C35 -> 14000 | G35: Despliegue a producción, infraestructura
A36: Senior - Cloud Engineer | B36: 15500 | C36: 1 | D36: =B36*C36 -> 15500 | G36: Configuración entorno productivo
A37: Product Owner | B37: 22000 | C37: 0.3 | D37: =B37*C37 -> 6600 | G37: Validación UAT y firma de aceptación
A38: COSTO MENSUAL EQUIPO FALL | D38: =SUM(D34:D37) -> 43600 | G38: Σ Salario × FTE de roles activos
A40: Duración fase Fall | B40: 1.5 | C40: meses | G40: QA final, UAT, despliegue, capacitación
A41: COSTO TOTAL FASE FALL | B41: =D38*B40 -> 65400 | G41: Fórmula: costo mensual × Duración
A44: COSTOS EXTRA WATER-SCRUM-FALL
A45: Documentación formal, auditorías, certificaciones, capacitación: requeridos por contrato de precio fijo y gobierno corporativo.
A47: Concepto | B47: Costo (Q) | C47: Fase | G47: Justificación
A48: Documentación formal extendida | B48: 20000 | C48: Water+Fall | G48: Planes, diagramas, manuales (PMBOK)
A49: Análisis de negocio profundo | B49: 15000 | C49: Water | G49: Requerimientos detallados pre-desarrollo
A50: Diseño arquitectónico formal | B50: 20000 | C50: Water | G50: Arquitectura completa antes de codear
A51: Auditoría externa de seguridad | B51: 30000 | C51: Fall | G51: Validación antes de producción
A52: UAT formal con cliente | B52: 15000 | C52: Fall | G52: Pruebas con pilotos y operadores reales
A53: Capacitación de usuarios | B53: 25000 | C53: Fall | G53: Pilotos, supervisores, administradores
A54: Soporte hypercare (1er mes) | B54: 30000 | C54: Post-Fall | G54: Equipo de guardia tras go-live
...

Sheet PMI
A1: ANÁLISIS FINANCIERO PMI — TransportesNova
A2: Reserva de Riesgos (EMV) · TMAR · ROI · ROA · Payback — Comparativa entre las 4 metodologías
A4: 1. PRESUPUESTO BASE POR METODOLOGÍA (vinculado de cada hoja)
A5: Concepto | B5: SCRUM | C5: KANBAN | D5: SCRUMBAN | E5: XP | F5: WSF | G5: Notas
A6: Costo Interno del Equipo | B6: =SCRUM!B24 -> 514250 | C6: =KANBAN!B25 -> 935000 | D6: =SCRUMBAN!B40 -> 423087.5 | E6: =XP!B32 -> 514250 | F6: ='Water Scrum Fall'!B15+'Water Scrum Fall'!B27+'Water Scrum Fall'!B41 -> 664168.28 | G6: Vinculado desde cada hoja de metodología
A7: Otros costos del proyecto (Sección 2) | B7: =B17 -> 35000 | C7: =B17 -> 35000 | D7: =B17 -> 35000 | E7: =B17 -> 35000 | F7: =B17+'Water Scrum Fall'!B55 -> 190000 | G7: Licencias, servidores, capacitación, etc.
A8: PRESUPUESTO BASE | B8: =B6+B7 -> 549250 | C8: =C6+C7 -> 970000 | D8: =D6+D7 -> 458087.5 | E8: =E6+E7 -> 549250 | F8: =F6+F7 -> 854168.28 | G8: Fórmula: Costo Interno + Otros costos
A10: 2. OTROS COSTOS DEL PROYECTO (común a todas las metodologías)
A11: Concepto | B11: Costo (Q) | G11: Justificación
A12: Licencias de software | B12: 8000 | G12: Herramientas Jira, GitHub, etc.
A13: Servidores y cloud | B13: 12000 | G13: AWS/Azure durante todo el proyecto
A14: Capacitación del equipo | B14: 5000 | G14: Onboarding y formación específica
A15: QA externo | B15: 6000 | G15: Auditoría de calidad puntual
A16: Documentación | B16: 4000 | G16: Manuales, diagramas, entregables
A17: TOTAL OTROS COSTOS | B17: =SUM(B12:B16) -> 35000 | G17: Mismo monto para las 4 metodologías
A19: 3. RESERVA DE RIESGOS — Valor Monetario Esperado (EMV) — PMBOK Gestión de Riesgos
A20: Fórmula EMV = Probabilidad × Impacto. Reserva de Riesgos = Σ EMV
A21: Riesgo identificado | B21: Probabilidad | C21: Impacto (Q) | D21: EMV (Q) | E21: Costo Mensual | F21: Tiempo | G21: Comentario
A22: Cambio de requerimientos del cliente | B22: 0.3 | C22: =E22*F22 -> 70125 | D22: =B22*C22 -> 21037.5 | E22: =Equipo!E13 -> 46750 | F22: 1.5 | G22: Alta probabilidad en proyectos ágiles
A23: Retraso técnico / curva de aprendizaje | B23: 0.25 | C23: =E23*F23 -> 23375 | D23: =B23*C23 -> 5843.75 | E23: =Equipo!E13 -> 46750 | F23: 0.5 | G23: Equipo junior incluido
A24: Disponibilidad de stakeholders | B24: 0.25 | C24: =E24*F24 -> 7012.5 | D24: =B24*C24 -> 1753.125 | E24: =Equipo!E13 -> 46750 | F24: 0.15 | G24: PO y SM a 50% FTE
A25: Defectos en producción | B25: 0.2 | C25: =E25*F25 -> 11687.5 | D25: =B25*C25 -> 2337.5 | E25: =Equipo!E13 -> 46750 | F25: 0.25 | G25: Mitigado en XP por pair programming
A26: Dependencias externas (cloud, API) | B26: 0.15 | C26: =E26*F26 -> 11687.5 | D26: =B26*C26 -> 1753.125 | E26: =Equipo!E13 -> 46750 | F26: 0.25 | G26: Servicios de terceros
A27: RESERVA DE RIESGOS TOTAL (Σ EMV) | D27: =SUM(D22:D26) -> 32725 | G27: Reserva común para las 4 metodologías
A29: 4. PRESUPUESTO INTERNO CON RIESGOS = Presupuesto Base + Reserva de Riesgos
A30: Concepto | B30: SCRUM | C30: KANBAN | D30: SCRUMBAN | E30: XP | F30: WSF | G30: Notas
A31: Presupuesto Base | B31: =B8 -> 549250 | C31: =C8 -> 970000 | D31: =D8 -> 458087.5 | E31: =E8 -> 549250 | F31: =F8 -> 854168.28
A32: (+) Reserva de Riesgos | B32: =D27 -> 32725 | C32: =D27 -> 32725 | D32: =D27 -> 32725 | E32: =D27 -> 32725 | F32: =D27 -> 32725
A33: PRESUPUESTO INTERNO CON RIESGOS | B33: =SUM(B31:B32) -> 581975 | C33: =SUM(C31:C32) -> 1002725 | D33: =SUM(D31:D32) -> 490812.5 | E33: =SUM(E31:E32) -> 581975 | F33: =SUM(F31:F32) -> 886893.28 | G33: Cost Baseline + Contingency Reserve (PMBOK)
A35: 5. PRECIO AL CLIENTE (Ingreso del Proyecto)
A36: Concepto | B36: SCRUM | C36: KANBAN | D36: SCRUMBAN | E36: XP | F36: WSF | G36: Notas
A37: Precio al Cliente (Ingreso Total) | B37: =SCRUM!B25 -> 1067925.8 | C37: =KANBAN!B24 -> 2400000 | D37: =SCRUMBAN!B39 -> 1057718.8 | E37: =XP!B27*XP!B19 -> 1320000 | F37: ='Water Scrum Fall'!B69 -> 1489396.9 | G37: Vinculado desde cada hoja
A39: 6. TMAR — Tasa Mínima Atractiva de Retorno (común a todas las metodologías)
A40: Fórmula: TMAR = Inflación + Riesgo + Rendimiento esperado
A41: Concepto | B41: Valor | G41: Justificación
A42: Inflación | B42: 0.05 | G42: Inflación esperada Guatemala (promedio)
A43: Riesgo del proyecto | B43: 0.08 | G43: Proyecto de complejidad normal
A44: Rendimiento esperado | B44: 0.25 | G44: Meta financiera de la empresa
A45: TMAR TOTAL | B45: =SUM(B42:B44) -> 0.38 | G45: Tasa mínima que el proyecto debe superar
A47: 7. BENEFICIOS ESPERADOS DEL SISTEMA (Ahorros anuales para TransportesNova)
...

Sheet Equipo
A1: TransportesNova — Equipo de Trabajo (Supuestos Compartidos)
A3: Rol | B3: Descripción | C3: Salario Mensual (Q) | D3: FTE Asignado | E3: Costo Asignado (Q)
A4: PO | B4: Product Owner | C4: 22000 | D4: 0.5 | E4: =C4*D4 -> 11000
A5: SM/Facilitador | B5: Scrum Master / Facilitador | C5: 16500 | D5: 0.5 | E5: =C5*D5 -> 8250
A6: JN1 | B6: Junior Full Stack 1 | C6: 9000 | D6: 0.5 | E6: =C6*D6 -> 4500
A7: JN2 | B7: Junior Full Stack 2 | C7: 9000 | D7: 0.5 | E7: =C7*D7 -> 4500
A8: QA | B8: QA Engineer | C8: 7500 | D8: 0.5 | E8: =C8*D8 -> 3750
A9: SN1 | B9: Senior - DevOps | C9: 14000 | D9: 0.5 | E9: =C9*D9 -> 7000
A10: SN2 | B10: Senior - Cloud Engineer | C10: 15500 | D10: 0.5 | E10: =C10*D10 -> 7750
A12: COSTO TOTAL MENSUAL | E12: =SUM(C4:C10) -> 93500
A13: COSTO INTERNO (50% FTE – sin overhead) | E13: =SUM(E4:E10) -> 46750

Sheet Backlog
A1: Clave | B1: Título Historia | C1: Épica | D1: Descripción Épica | E1: Tipo | F1: SP | G1: Prioridad | H1: Estado
A2: EP01 — Usuarios, Roles y Permisos
A3: SCRUM-11 | B3: Registrar usuarios internos | C3: EP01 | D3: Usuarios, Roles y Permisos | E3: Historia | F3: 5 | G3: High | H3: Backlog
A4: SCRUM-12 | B4: Consultar listado de usuarios internos | C4: EP01 | D4: Usuarios, Roles y Permisos | E4: Historia | F4: 3 | G4: Medium | H4: Backlog
A5: SCRUM-13 | B5: Buscar usuarios por criterios | C5: EP01 | D5: Usuarios, Roles y Permisos | E5: Historia | F5: 3 | G5: Medium | H5: Backlog
A6: SCRUM-14 | B6: Editar información de usuarios | C6: EP01 | D6: Usuarios, Roles y Permisos | E6: Historia | F6: 5 | G6: Medium | H6: Backlog
A7: SCRUM-15 | B7: Inactivar usuarios internos | C7: EP01 | D7: Usuarios, Roles y Permisos | E7: Historia | F7: 3 | G7: Medium | H7: Backlog
A8: SCRUM-16 | B8: Asignar roles a usuarios | C8: EP01 | D8: Usuarios, Roles y Permisos | E8: Historia | F8: 5 | G8: High | H8: Backlog
A9: SCRUM-17 | B9: Restringir acceso según rol | C9: EP01 | D9: Usuarios, Roles y Permisos | E9: Historia | F9: 8 | G9: High | H9: Backlog
A10: SCRUM-18 | B10: Restablecer credenciales de acceso | C10: EP01 | D10: Usuarios, Roles y Permisos | E10: Historia | F10: 5 | G10: Medium | H10: Backlog
A11: SCRUM-19 | B11: Auditar cambios de usuarios y permisos | C11: EP01 | D11: Usuarios, Roles y Permisos | E11: Historia | F11: 8 | G11: Low | H11: Backlog
A12: Subtotal EP01 — 9 historias | F12: =SUM(F3:F11) -> 45
A14: EP02 — Gestión de Flota y Unidades
A15: SCRUM-20 | B15: Registrar unidades de transporte | C15: EP02 | D15: Gestión de Flota y Unidades | E15: Historia | F15: 5 | G15: High | H15: Backlog
A16: SCRUM-21 | B16: Consultar listado de unidades | C16: EP02 | D16: Gestión de Flota y Unidades | E16: Historia | F16: 3 | G16: Medium | H16: Backlog
A17: SCRUM-22 | B17: Buscar unidades por placa o tipo | C17: EP02 | D17: Gestión de Flota y Unidades | E17: Historia | F17: 3 | G17: Medium | H17: Backlog
A18: SCRUM-23 | B18: Editar información de unidades | C18: EP02 | D18: Gestión de Flota y Unidades | E18: Historia | F18: 5 | G18: Medium | H18: Backlog
A19: SCRUM-24 | B19: Cambiar estado operativo de una unidad | C19: EP02 | D19: Gestión de Flota y Unidades | E19: Historia | F19: 5 | G19: High | H19: Backlog
A20: SCRUM-25 | B20: Consultar detalle de una unidad | C20: EP02 | D20: Gestión de Flota y Unidades | E20: Historia | F20: 3 | G20: Medium | H20: Backlog
A21: SCRUM-26 | B21: Validar disponibilidad antes de asignar unidad | C21: EP02 | D21: Gestión de Flota y Unidades | E21: Historia | F21: 8 | G21: High | H21: Backlog
A22: SCRUM-27 | B22: Registrar capacidad y tipo de carga soportada | C22: EP02 | D22: Gestión de Flota y Unidades | E22: Historia | F22: 5 | G22: High | H22: Backlog
A23: SCRUM-28 | B23: Consultar historial de uso por unidad | C23: EP02 | D23: Gestión de Flota y Unidades | E23: Historia | F23: 8 | G23: Medium | H23: Backlog
A24: SCRUM-29 | B24: Dar de baja una unidad | C24: EP02 | D24: Gestión de Flota y Unidades | E24: Historia | F24: 5 | G24: Low | H24: Backlog
A25: SCRUM-30 | B25: Registrar documentación legal de una unidad | C25: EP02 | D25: Gestión de Flota y Unidades | E25: Historia | F25: 5 | G25: High | H25: Backlog
A26: SCRUM-31 | B26: Alertar vencimiento de documentos de unidad | C26: EP02 | D26: Gestión de Flota y Unidades | E26: Historia | F26: 5 | G26: Medium | H26: Backlog
A27: Subtotal EP02 — 12 historias | F27: =SUM(F15:F26) -> 60
A29: EP03 — Gestión de Pilotos
A30: SCRUM-32 | B30: Registrar pilotos | C30: EP03 | D30: Gestión de Pilotos | E30: Historia | F30: 5 | G30: High | H30: Backlog
A31: SCRUM-33 | B31: Consultar listado de pilotos | C31: EP03 | D31: Gestión de Pilotos | E31: Historia | F31: 3 | G31: Medium | H31: Backlog
A32: SCRUM-34 | B32: Actualizar información de pilotos | C32: EP03 | D32: Gestión de Pilotos | E32: Historia | F32: 5 | G32: Medium | H32: Backlog
A33: SCRUM-35 | B33: Registrar disponibilidad de pilotos | C33: EP03 | D33: Gestión de Pilotos | E33: Historia | F33: 5 | G33: High | H33: Backlog
A34: SCRUM-36 | B34: Validar licencia y vencimiento | C34: EP03 | D34: Gestión de Pilotos | E34: Historia | F34: 8 | G34: High | H34: Backlog
A35: SCRUM-37 | B35: Impedir doble asignación de piloto | C35: EP03 | D35: Gestión de Pilotos | E35: Historia | F35: 8 | G35: High | H35: Backlog
A36: SCRUM-38 | B36: Consultar historial operativo del piloto | C36: EP03 | D36: Gestión de Pilotos | E36: Historia | F36: 8 | G36: Medium | H36: Backlog
A37: SCRUM-39 | B37: Inactivar pilotos | C37: EP03 | D37: Gestión de Pilotos | E37: Historia | F37: 3 | G37: Medium | H37: Backlog
A38: SCRUM-40 | B38: Registrar observaciones de desempeño | C38: EP03 | D38: Gestión de Pilotos | E38: Historia | F38: 5 | G38: Medium | H38: Backlog
A39: SCRUM-41 | B39: Registrar documentación personal del piloto | C39: EP03 | D39: Gestión de Pilotos | E39: Historia | F39: 5 | G39: Medium | H39: Backlog
A40: SCRUM-42 | B40: Alertar vencimiento de licencia del piloto | C40: EP03 | D40: Gestión de Pilotos | E40: Historia | F40: 5 | G40: High | H40: Backlog
A41: Subtotal EP03 — 11 historias | F41: =SUM(F30:F40) -> 60
A43: EP04 — Rutas y Planificación Operativa
...

Sheet MVP
A1: Clave | B1: Título Historia | C1: Épica | D1: Descripción Épica | E1: Tipo | F1: SP | G1: Prioridad | H1: Estado
A2: EP01 — Usuarios, Roles y Permisos
A3: SCRUM-11 | B3: Registrar usuarios internos | C3: EP01 | D3: Usuarios, Roles y Permisos | E3: Historia | F3: 5 | G3: High | H3: Backlog
A4: SCRUM-16 | B4: Asignar roles a usuarios | C4: EP01 | D4: Usuarios, Roles y Permisos | E4: Historia | F4: 5 | G4: High | H4: Backlog
A5: SCRUM-17 | B5: Restringir acceso según rol | C5: EP01 | D5: Usuarios, Roles y Permisos | E5: Historia | F5: 8 | G5: High | H5: Backlog
A6: Subtotal EP01 — 3 historias | F6: =SUM(F3:F5) -> 18
A8: EP02 — Gestión de Flota y Unidades
A9: SCRUM-20 | B9: Registrar unidades de transporte | C9: EP02 | D9: Gestión de Flota y Unidades | E9: Historia | F9: 5 | G9: High | H9: Backlog
A10: SCRUM-21 | B10: Consultar listado de unidades | C10: EP02 | D10: Gestión de Flota y Unidades | E10: Historia | F10: 3 | G10: Medium | H10: Backlog
A11: SCRUM-24 | B11: Cambiar estado operativo de una unidad | C11: EP02 | D11: Gestión de Flota y Unidades | E11: Historia | F11: 5 | G11: High | H11: Backlog
A12: SCRUM-26 | B12: Validar disponibilidad antes de asignar unidad | C12: EP02 | D12: Gestión de Flota y Unidades | E12: Historia | F12: 8 | G12: High | H12: Backlog
A13: SCRUM-27 | B13: Registrar capacidad y tipo de carga soportada | C13: EP02 | D13: Gestión de Flota y Unidades | E13: Historia | F13: 5 | G13: High | H13: Backlog
A14: Subtotal EP02 — 5 historias | F14: =SUM(F9:F13) -> 26
A16: EP03 — Gestión de Pilotos
A17: SCRUM-32 | B17: Registrar pilotos | C17: EP03 | D17: Gestión de Pilotos | E17: Historia | F17: 5 | G17: High | H17: Backlog
A18: SCRUM-33 | B18: Consultar listado de pilotos | C18: EP03 | D18: Gestión de Pilotos | E18: Historia | F18: 3 | G18: Medium | H18: Backlog
A19: SCRUM-35 | B19: Registrar disponibilidad de pilotos | C19: EP03 | D19: Gestión de Pilotos | E19: Historia | F19: 5 | G19: High | H19: Backlog
A20: SCRUM-36 | B20: Validar licencia y vencimiento | C20: EP03 | D20: Gestión de Pilotos | E20: Historia | F20: 8 | G20: High | H20: Backlog
A21: SCRUM-37 | B21: Impedir doble asignación de piloto | C21: EP03 | D21: Gestión de Pilotos | E21: Historia | F21: 8 | G21: High | H21: Backlog
A22: Subtotal EP03 — 5 historias | F22: =SUM(F17:F21) -> 29
A24: EP04 — Rutas y Planificación Operativa
A25: SCRUM-43 | B25: Registrar rutas | C25: EP04 | D25: Rutas y Planificación Operativa | E25: Historia | F25: 5 | G25: High | H25: Backlog
A26: SCRUM-44 | B26: Consultar rutas registradas | C26: EP04 | D26: Rutas y Planificación Operativa | E26: Historia | F26: 3 | G26: Medium | H26: Backlog
A27: SCRUM-46 | B27: Programar horarios de salida y llegada | C27: EP04 | D27: Rutas y Planificación Operativa | E27: Historia | F27: 5 | G27: High | H27: Backlog
A28: SCRUM-47 | B28: Asignar unidad a una ruta | C28: EP04 | D28: Rutas y Planificación Operativa | E28: Historia | F28: 5 | G28: High | H28: Backlog
A29: SCRUM-48 | B29: Asignar piloto a una ruta | C29: EP04 | D29: Rutas y Planificación Operativa | E29: Historia | F29: 5 | G29: High | H29: Backlog
A30: SCRUM-49 | B30: Validar coherencia de asignaciones de ruta | C30: EP04 | D30: Rutas y Planificación Operativa | E30: Historia | F30: 8 | G30: High | H30: Backlog
A31: SCRUM-52 | B31: Consultar calendario operativo de rutas | C31: EP04 | D31: Rutas y Planificación Operativa | E31: Historia | F31: 8 | G31: Medium | H31: Backlog
A32: Subtotal EP04 — 7 historias | F32: =SUM(F25:F31) -> 39
A34: EP06 — Gestión de Incidencias
A35: SCRUM-69 | B35: Registrar incidencias en ruta | C35: EP06 | D35: Gestión de Incidencias | E35: Historia | F35: 5 | G35: High | H35: Backlog
A36: SCRUM-70 | B36: Clasificar tipo de incidencia | C36: EP06 | D36: Gestión de Incidencias | E36: Historia | F36: 3 | G36: High | H36: Backlog
A37: SCRUM-71 | B37: Asignar prioridad a incidencias | C37: EP06 | D37: Gestión de Incidencias | E37: Historia | F37: 3 | G37: High | H37: Backlog
A38: SCRUM-72 | B38: Dar seguimiento al estado de una incidencia | C38: EP06 | D38: Gestión de Incidencias | E38: Historia | F38: 5 | G38: High | H38: Backlog
A39: SCRUM-75 | B39: Escalar incidencias críticas | C39: EP06 | D39: Gestión de Incidencias | E39: Historia | F39: 8 | G39: High | H39: Backlog
A40: SCRUM-76 | B40: Cerrar incidencias con resolución documentada | C40: EP06 | D40: Gestión de Incidencias | E40: Historia | F40: 5 | G40: High | H40: Backlog
A41: Subtotal EP06 — 6 historias | F41: =SUM(F35:F40) -> 29
A43: EP09 — Dashboard Ejecutivo y Reportes
A44: SCRUM-102 | B44: Visualizar indicadores generales en dashboard | C44: EP09 | D44: Dashboard Ejecutivo y Reportes | E44: Historia | F44: 8 | G44: High | H44: Backlog
A45: SCRUM-103 | B45: Mostrar total de unidades activas | C45: EP09 | D45: Dashboard Ejecutivo y Reportes | E45: Historia | F45: 3 | G45: High | H45: Backlog
...
